Workbook
Name H1_: Matrizes!$B$3:$C$4
Name H2_: Matrizes!$B$7:$E$10
Name H3_: Matrizes!$B$13:$I$20

Sheet E1
B1: y | F1: q0 | I1: q1 | L1: q2
A2: Estados : | B2: 0 | C2: 1 | F2: 0 | G2: 1 | I2: 0 | J2: 1 | L2: 0 | M2: 1
A3: Amplitudes : | B3: 0 | C3: 1 | F3: 1 | G3: 0 | I3: 1 | J3: 0 | L3: 1 | M3: 0
F5: q0.q1
F6: 0.0 | G6: 0.1 | H6: 1.0 | I6: 1.1
F7: =$F$3*I3 -> 1 | G7: =$F$3*J3 -> 0 | H7: =$G$3*I3 -> 0 | I7: =$G$3*J3 -> 0
P8: Medidas são valores
B9: Amplitudes | F9: q0.q1.q2 | P9: observáveis (estão neste mundo)
B10: são valores NÃO observáveis | F10: 0.0.0 | G10: 0.0.1 | H10: 0.1.0 | I10: 0.1.1 | J10: 1.0.0 | K10: 1.0.1 | L10: 1.1.0 | M10: 1.1.1 | P10: q0.q1.q2
B11: (estão no outro mundo) | F11: =$F$7*L3 -> 1 | G11: =$F$7*M3 -> 0 | H11: =$G$7*L3 -> 0 | I11: =$G$7*M3 -> 0 | J11: =$H$7*L3 -> 0 | K11: =$H$7*M3 -> 0 | L11: =$I$7*L3 -> 0 | M11: =$I$7*M3 -> 0 | P11: =INDEX(F10:M10,MATCH(RAND(),F13:M13,1)) -> 0.0.0
E12: Prob.Ind. | F12: =F11^2/SUMPRODUCT($F11:$M11,$F11:$M11) -> 1 | G12: =G11^2/SUMPRODUCT($F11:$M11,$F11:$M11) -> 0 | H12: =H11^2/SUMPRODUCT($F11:$M11,$F11:$M11) -> 0 | I12: =I11^2/SUMPRODUCT($F11:$M11,$F11:$M11) -> 0 | J12: =J11^2/SUMPRODUCT($F11:$M11,$F11:$M11) -> 0 | K12: =K11^2/SUMPRODUCT($F11:$M11,$F11:$M11) -> 0 | L12: =L11^2/SUMPRODUCT($F11:$M11,$F11:$M11) -> 0 | M12: =M11^2/SUMPRODUCT($F11:$M11,$F11:$M11) -> 0
E13: Prob.Ac. | F13: 0 | G13: =F13+F12 -> 1 | H13: =G13+G12 -> 1 | I13: =H13+H12 -> 1 | J13: =I13+I12 -> 1 | K13: =J13+J12 -> 1 | L13: =K13+K12 -> 1 | M13: =L13+L12 -> 1 | N13: =M13+M12 -> 1
P14: Medidas são valores
B15: y.H1 | F15: (q0.q1.q2).H3 | P15: observáveis (estão neste mundo)
A16: Estados : | B16: 0 | C16: 1 | E16: Input ao | F16: 0.0.0 | G16: 0.0.1 | H16: 0.1.0 | I16: 0.1.1 | J16: 1.0.0 | K16: 1.0.1 | L16: 1.1.0 | M16: 1.1.1 | P16: q0.q1.q2 | Q16: P(q0.q1.q2) | T16: e0 = (y.H1) x (q0.q1.q2.H3)
A17: Amplitudes : | B17: {=MMULT(B3:C3,Matrizes!B3:C4)} -> 1 | C17: -1 | E17: DB Quântico-> | F17: {=MMULT(F11:M11,Matrizes!B13:I20)} -> 1 | G17: 1 | H17: 1 | I17: 1 | J17: 1 | K17: 1 | L17: 1 | M17: 1 | P17: =INDEX(F16:M16,MATCH(RAND(),F19:M19,1)) -> 1.1.1 | Q17: =INDEX(F17:M17,MATCH(P17,F16:M16,0))^2/SUMPRODUCT(F17:M17,F17:M17) -> 0.125 | T17: =$B$17*F17 -> 1 | U17: =$B$17*G17 -> 1 | V17: =$B$17*H17 -> 1 | W17: =$B$17*I17 -> 1 | X17: =$B$17*J17 -> 1 | Y17: =$B$17*K17 -> 1 | Z17: =$B$17*L17 -> 1 | AA17: =$B$17*M17 -> 1 | AB17: =$C$17*F17 -> -1 | AC17: =$C$17*G17 -> -1 | AD17: =$C$17*H17 -> -1 | AE17: =$C$17*I17 -> -1 | AF17: =$C$17*J17 -> -1 | AG17: =$C$17*K17 -> -1 | AH17: =$C$17*L17 -> -1 | AI17: =$C$17*M17 -> -1
E18: Prob.Ind. | F18: =F17^2/SUMPRODUCT($F17:$M17,$F17:$M17) -> 0.125 | G18: =G17^2/SUMPRODUCT($F17:$M17,$F17:$M17) -> 0.125 | H18: =H17^2/SUMPRODUCT($F17:$M17,$F17:$M17) -> 0.125 | I18: =I17^2/SUMPRODUCT($F17:$M17,$F17:$M17) -> 0.125 | J18: =J17^2/SUMPRODUCT($F17:$M17,$F17:$M17) -> 0.125 | K18: =K17^2/SUMPRODUCT($F17:$M17,$F17:$M17) -> 0.125 | L18: =L17^2/SUMPRODUCT($F17:$M17,$F17:$M17) -> 0.125 | M18: =M17^2/SUMPRODUCT($F17:$M17,$F17:$M17) -> 0.125
E19: Prob.Ac. | F19: 0 | G19: =F19+F18 -> 0.125 | H19: =G19+G18 -> 0.25 | I19: =H19+H18 -> 0.375 | J19: =I19+I18 -> 0.5 | K19: =J19+J18 -> 0.625 | L19: =K19+K18 -> 0.75 | M19: =L19+L18 -> 0.875 | N19: =M19+M18 -> 1
F21: e1 = [(y.H1) x (q0.q1.q2.H3)].Banco de Dados (apenas as amplitudes de q0.q1.q2)
E22: Output do | F22: 0.0.0 | G22: 0.0.1 | H22: 0.1.0 | I22: 0.1.1 | J22: 1.0.0 | K22: 1.0.1 | L22: 1.1.0 | M22: 1.1.1 | T22: e1 = e0 . Banco de Dados
E23: DB Quântico-> | F23: {=T23:AA23} -> 1 | G23: 1 | H23: 1 | I23: 1 | J23: -1 | K23: 1 | L23: 1 | M23: 1 | T23: {=MMULT(T17:AI17,TRANSPOSE(Matrizes!B28:Q43))} -> 1 | U23: 1 | V23: 1 | W23: 1 | X23: -1 | Y23: 1 | Z23: 1 | AA23: 1 | AB23: -1 | AC23: -1 | AD23: -1 | AE23: -1 | AF23: 1 | AG23: -1 | AH23: -1 | AI23: -1
P25: Medidas são valores
A26: A matriz de inversão calcula: | F26: e2 = e1 . [I2 x Matriz de Inversão] (apenas as amplitudes de q0.q1.q2) | P26: observáveis (estão neste mundo)
A27: Zi = m - ( Xi - m ) | E27: Input ao | F27: 0.0.0 | G27: 0.0.1 | H27: 0.1.0 | I27: 0.1.1 | J27: 1.0.0 | K27: 1.0.1 | L27: 1.1.0 | M27: 1.1.1 | P27: q0.q1.q2 | Q27: P(q0.q1.q2) | T27: e2 = e1 . [I2 x Matriz de Inversão]
A28: ou Z = (2.A - I).X | E28: DB Quântico-> | F28: {=T28:AA28} -> 0.5 | G28: 0.5 | H28: 0.5 | I28: 0.5 | J28: 2.5 | K28: 0.5 | L28: 0.5 | M28: 0.5 | P28: =INDEX(F27:M27,MATCH(RAND(),F30:M30,1)) -> 1.0.0 | Q28: =INDEX(F28:M28,MATCH(P28,F27:M27,0))^2/SUMPRODUCT(F28:M28,F28:M28) -> 0.78125 | T28: {=MMULT(T23:AI23,Matrizes!U13:AJ28)} -> 0.5 | U28: 0.5 | V28: 0.5 | W28: 0.5 | X28: 2.5 | Y28: 0.5 | Z28: 0.5 | AA28: 0.5 | AB28: -0.5 | AC28: -0.5 | AD28: -0.5 | AE28: -0.5 | AF28: -2.5 | AG28: -0.5 | AH28: -0.5 | AI28: -0.5
A29: onde A é uma matriz onde todos | E29: Prob.Ind. | F29: =F28^2/SUMPRODUCT($F28:$M28,$F28:$M28) -> 0.03125 | G29: =G28^2/SUMPRODUCT($F28:$M28,$F28:$M28) -> 0.03125 | H29: =H28^2/SUMPRODUCT($F28:$M28,$F28:$M28) -> 0.03125 | I29: =I28^2/SUMPRODUCT($F28:$M28,$F28:$M28) -> 0.03125 | J29: =J28^2/SUMPRODUCT($F28:$M28,$F28:$M28) -> 0.78125 | K29: =K28^2/SUMPRODUCT($F28:$M28,$F28:$M28) -> 0.03125 | L29: =L28^2/SUMPRODUCT($F28:$M28,$F28:$M28) -> 0.03125 | M29: =M28^2/SUMPRODUCT($F28:$M28,$F28:$M28) -> 0.03125
A30: os elementos são iguais a 1/n ( neste | E30: Prob.Ac. | F30: 0 | G30: =F30+F29 -> 0.03125 | H30: =G30+G29 -> 0.0625 | I30: =H30+H29 -> 0.09375 | J30: =I30+I29 -> 0.125 | K30: =J30+J29 -> 0.90625 | L30: =K30+K29 -> 0.9375 | M30: =L30+L29 -> 0.96875 | N30: =M30+M29 -> 1
A31: exemplo n=8 ) e I é uma matriz identidade
A32: a qual neste exemplo é [8x8] | F32: e3 = e2.Banco de Dados (apenas as amplitudes de q0.q1.q2)
E33: Output do | F33: 0.0.0 | G33: 0.0.1 | H33: 0.1.0 | I33: 0.1.1 | J33: 1.0.0 | K33: 1.0.1 | L33: 1.1.0 | M33: 1.1.1 | T33: e3 = e2 . Banco de Dados
E34: DB Quântico-> | F34: {=T34:AA34} -> 0.5 | G34: 0.5 | H34: 0.5 | I34: 0.5 | J34: -2.5 | K34: 0.5 | L34: 0.5 | M34: 0.5 | T34: {=MMULT(T28:AI28,TRANSPOSE(Matrizes!B28:Q43))} -> 0.5 | U34: 0.5 | V34: 0.5 | W34: 0.5 | X34: -2.5 | Y34: 0.5 | Z34: 0.5 | AA34: 0.5 | AB34: -0.5 | AC34: -0.5 | AD34: -0.5 | AE34: -0.5 | AF34: 2.5 | AG34: -0.5 | AH34: -0.5 | AI34: -0.5
P36: Medidas são valores
B37: Amplitudes | F37: e4 = e3 . [I2 x Matriz de Inversão] (apenas as amplitudes de q0.q1.q2) | P37: observáveis (estão neste mundo)
B38: são valores NÃO observáveis | F38: 0.0.0 | G38: 0.0.1 | H38: 0.1.0 | I38: 0.1.1 | J38: 1.0.0 | K38: 1.0.1 | L38: 1.1.0 | M38: 1.1.1 | P38: q0.q1.q2 | Q38: P(q0.q1.q2) | R38: Resultado | T38: e4 = e3 . [I2 x Matriz de Inversão]
B39: (estão no outro mundo) | F39: {=T39:AA39} -> -0.25 | G39: -0.25 | H39: -0.25 | I39: -0.25 | J39: 2.75 | K39: -0.25 | L39: -0.25 | M39: -0.25 | P39: =INDEX(F38:M38,MATCH(RAND(),F41:M41,1)) -> 1.0.0 | Q39: =INDEX(F39:M39,MATCH(P39,F38:M38,0))^2/SUMPRODUCT(F39:M39,F39:M39) -> 0.9453125 | R39: =INDEX(Matrizes!W33:W40,MATCH('E1'!P39,Matrizes!U33:U40,0)) -> Fernanda | T39: {=MMULT(T34:AI34,Matrizes!U13:AJ28)} -> -0.25 | U39: -0.25 | V39: -0.25 | W39: -0.25 | X39: 2.75 | Y39: -0.25 | Z39: -0.25 | AA39: -0.25 | AB39: 0.25 | AC39: 0.25 | AD39: 0.25 | AE39: 0.25 | AF39: -2.75 | AG39: 0.25 | AH39: 0.25 | AI39: 0.25
E40: Prob.Ind. | F40: =F39^2/SUMPRODUCT($F39:$M39,$F39:$M39) -> 0.0078125 | G40: =G39^2/SUMPRODUCT($F39:$M39,$F39:$M39) -> 0.0078125 | H40: =H39^2/SUMPRODUCT($F39:$M39,$F39:$M39) -> 0.0078125 | I40: =I39^2/SUMPRODUCT($F39:$M39,$F39:$M39) -> 0.0078125 | J40: =J39^2/SUMPRODUCT($F39:$M39,$F39:$M39) -> 0.9453125 | K40: =K39^2/SUMPRODUCT($F39:$M39,$F39:$M39) -> 0.0078125 | L40: =L39^2/SUMPRODUCT($F39:$M39,$F39:$M39) -> 0.0078125 | M40: =M39^2/SUMPRODUCT($F39:$M39,$F39:$M39) -> 0.0078125
E41: Prob.Ac. | F41: 0 | G41: =F41+F40 -> 0.0078125 | H41: =G41+G40 -> 0.015625 | I41: =H41+H40 -> 0.0234375 | J41: =I41+I40 -> 0.03125 | K41: =J41+J40 -> 0.9765625 | L41: =K41+K40 -> 0.984375 | M41: =L41+L40 -> 0.9921875 | N41: =M41+M40 -> 1

Sheet Matrizes
C2: H1 | L2: A3 = 1/n | M2: n= | N2: =2^3 -> 8 | U2: I3
B3: 1 | C3: 1 | L3: {=1/N2} -> 0.125 | M3: 0.125 | N3: 0.125 | O3: 0.125 | P3: 0.125 | Q3: 0.125 | R3: 0.125 | S3: 0.125 | U3: 1 | V3: 0 | W3: 0 | X3: 0 | Y3: 0 | Z3: 0 | AA3: 0 | AB3: 0
B4: 1 | C4: -1 | L4: 0.125 | M4: 0.125 | N4: 0.125 | O4: 0.125 | P4: 0.125 | Q4: 0.125 | R4: 0.125 | S4: 0.125 | U4: 0 | V4: 1 | W4: 0 | X4: 0 | Y4: 0 | Z4: 0 | AA4: 0 | AB4: 0
L5: 0.125 | M5: 0.125 | N5: 0.125 | O5: 0.125 | P5: 0.125 | Q5: 0.125 | R5: 0.125 | S5: 0.125 | U5: 0 | V5: 0 | W5: 1 | X5: 0 | Y5: 0 | Z5: 0 | AA5: 0 | AB5: 0
D6: H2 | H6: I2 | L6: 0.125 | M6: 0.125 | N6: 0.125 | O6: 0.125 | P6: 0.125 | Q6: 0.125 | R6: 0.125 | S6: 0.125 | U6: 0 | V6: 0 | W6: 0 | X6: 1 | Y6: 0 | Z6: 0 | AA6: 0 | AB6: 0
B7: {=B3*B3:C4} -> 1 | C7: 1 | D7: {=C3*B3:C4} -> 1 | E7: 1 | G7: 1 | H7: 0 | L7: 0.125 | M7: 0.125 | N7: 0.125 | O7: 0.125 | P7: 0.125 | Q7: 0.125 | R7: 0.125 | S7: 0.125 | U7: 0 | V7: 0 | W7: 0 | X7: 0 | Y7: 1 | Z7: 0 | AA7: 0 | AB7: 0
B8: 1 | C8: -1 | D8: 1 | E8: -1 | G8: 0 | H8: 1 | L8: 0.125 | M8: 0.125 | N8: 0.125 | O8: 0.125 | P8: 0.125 | Q8: 0.125 | R8: 0.125 | S8: 0.125 | U8: 0 | V8: 0 | W8: 0 | X8: 0 | Y8: 0 | Z8: 1 | AA8: 0 | AB8: 0
B9: {=B4*B3:C4} -> 1 | C9: 1 | D9: {=C4*B3:C4} -> -1 | E9: -1 | L9: 0.125 | M9: 0.125 | N9: 0.125 | O9: 0.125 | P9: 0.125 | Q9: 0.125 | R9: 0.125 | S9: 0.125 | U9: 0 | V9: 0 | W9: 0 | X9: 0 | Y9: 0 | Z9: 0 | AA9: 1 | AB9: 0
B10: 1 | C10: -1 | D10: -1 | E10: 1 | L10: 0.125 | M10: 0.125 | N10: 0.125 | O10: 0.125 | P10: 0.125 | Q10: 0.125 | R10: 0.125 | S10: 0.125 | U10: 0 | V10: 0 | W10: 0 | X10: 0 | Y10: 0 | Z10: 0 | AA10: 0 | AB10: 1
F12: H3 | L12: Matriz de Inversão em Relação à Média = (2.A3 - I) = Minv | U12: I2 x Minv
B13: {=B3*B7:E10} -> 1 | C13: 1 | D13: 1 | E13: 1 | F13: {=C3*B7:E10} -> 1 | G13: 1 | H13: 1 | I13: 1 | L13: {=2*(L3:S10)-(U3:AB10)} -> -0.75 | M13: 0.25 | N13: 0.25 | O13: 0.25 | P13: 0.25 | Q13: 0.25 | R13: 0.25 | S13: 0.25 | U13: {=G7*L13:S20} -> -0.75 | V13: 0.25 | W13: 0.25 | X13: 0.25 | Y13: 0.25 | Z13: 0.25 | AA13: 0.25 | AB13: 0.25 | AC13: {=H7*L13:S20} -> 0 | AD13: 0 | AE13: 0 | AF13: 0 | AG13: 0 | AH13: 0 | AI13: 0 | AJ13: 0
B14: 1 | C14: -1 | D14: 1 | E14: -1 | F14: 1 | G14: -1 | H14: 1 | I14: -1 | L14: 0.25 | M14: -0.75 | N14: 0.25 | O14: 0.25 | P14: 0.25 | Q14: 0.25 | R14: 0.25 | S14: 0.25 | U14: 0.25 | V14: -0.75 | W14: 0.25 | X14: 0.25 | Y14: 0.25 | Z14: 0.25 | AA14: 0.25 | AB14: 0.25 | AC14: 0 | AD14: 0 | AE14: 0 | AF14: 0 | AG14: 0 | AH14: 0 | AI14: 0 | AJ14: 0
B15: 1 | C15: 1 | D15: -1 | E15: -1 | F15: 1 | G15: 1 | H15: -1 | I15: -1 | L15: 0.25 | M15: 0.25 | N15: -0.75 | O15: 0.25 | P15: 0.25 | Q15: 0.25 | R15: 0.25 | S15: 0.25 | U15: 0.25 | V15: 0.25 | W15: -0.75 | X15: 0.25 | Y15: 0.25 | Z15: 0.25 | AA15: 0.25 | AB15: 0.25 | AC15: 0 | AD15: 0 | AE15: 0 | AF15: 0 | AG15: 0 | AH15: 0 | AI15: 0 | AJ15: 0
B16: 1 | C16: -1 | D16: -1 | E16: 1 | F16: 1 | G16: -1 | H16: -1 | I16: 1 | L16: 0.25 | M16: 0.25 | N16: 0.25 | O16: -0.75 | P16: 0.25 | Q16: 0.25 | R16: 0.25 | S16: 0.25 | U16: 0.25 | V16: 0.25 | W16: 0.25 | X16: -0.75 | Y16: 0.25 | Z16: 0.25 | AA16: 0.25 | AB16: 0.25 | AC16: 0 | AD16: 0 | AE16: 0 | AF16: 0 | AG16: 0 | AH16: 0 | AI16: 0 | AJ16: 0
B17: {=B4*B7:E10} -> 1 | C17: 1 | D17: 1 | E17: 1 | F17: {=C4*B7:E10} -> -1 | G17: -1 | H17: -1 | I17: -1 | L17: 0.25 | M17: 0.25 | N17: 0.25 | O17: 0.25 | P17: -0.75 | Q17: 0.25 | R17: 0.25 | S17: 0.25 | U17: 0.25 | V17: 0.25 | W17: 0.25 | X17: 0.25 | Y17: -0.75 | Z17: 0.25 | AA17: 0.25 | AB17: 0.25 | AC17: 0 | AD17: 0 | AE17: 0 | AF17: 0 | AG17: 0 | AH17: 0 | AI17: 0 | AJ17: 0
B18: 1 | C18: -1 | D18: 1 | E18: -1 | F18: -1 | G18: 1 | H18: -1 | I18: 1 | L18: 0.25 | M18: 0.25 | N18: 0.25 | O18: 0.25 | P18: 0.25 | Q18: -0.75 | R18: 0.25 | S18: 0.25 | U18: 0.25 | V18: 0.25 | W18: 0.25 | X18: 0.25 | Y18: 0.25 | Z18: -0.75 | AA18: 0.25 | AB18: 0.25 | AC18: 0 | AD18: 0 | AE18: 0 | AF18: 0 | AG18: 0 | AH18: 0 | AI18: 0 | AJ18: 0
B19: 1 | C19: 1 | D19: -1 | E19: -1 | F19: -1 | G19: -1 | H19: 1 | I19: 1 | L19: 0.25 | M19: 0.25 | N19: 0.25 | O19: 0.25 | P19: 0.25 | Q19: 0.25 | R19: -0.75 | S19: 0.25 | U19: 0.25 | V19: 0.25 | W19: 0.25 | X19: 0.25 | Y19: 0.25 | Z19: 0.25 | AA19: -0.75 | AB19: 0.25 | AC19: 0 | AD19: 0 | AE19: 0 | AF19: 0 | AG19: 0 | AH19: 0 | AI19: 0 | AJ19: 0
B20: 1 | C20: -1 | D20: -1 | E20: 1 | F20: -1 | G20: 1 | H20: 1 | I20: -1 | L20: 0.25 | M20: 0.25 | N20: 0.25 | O20: 0.25 | P20: 0.25 | Q20: 0.25 | R20: 0.25 | S20: -0.75 | U20: 0.25 | V20: 0.25 | W20: 0.25 | X20: 0.25 | Y20: 0.25 | Z20: 0.25 | AA20: 0.25 | AB20: -0.75 | AC20: 0 | AD20: 0 | AE20: 0 | AF20: 0 | AG20: 0 | AH20: 0 | AI20: 0 | AJ20: 0
U21: {=G8*L13:S20} -> 0 | V21: 0 | W21: 0 | X21: 0 | Y21: 0 | Z21: 0 | AA21: 0 | AB21: 0 | AC21: {=H8*L13:S20} -> -0.75 | AD21: 0.25 | AE21: 0.25 | AF21: 0.25 | AG21: 0.25 | AH21: 0.25 | AI21: 0.25 | AJ21: 0.25
B22: Banco de Dados em Formato Matricial - Preparado para uma consulta via Qubits | J22: Coluna -> Linha | U22: 0 | V22: 0 | W22: 0 | X22: 0 | Y22: 0 | Z22: 0 | AA22: 0 | AB22: 0 | AC22: 0.25 | AD22: -0.75 | AE22: 0.25 | AF22: 0.25 | AG22: 0.25 | AH22: 0.25 | AI22: 0.25 | AJ22: 0.25
B23: f(1.0.0) = 1 // Demais f(q2.q1.q0) = 0 | J23: [y].[q2.q1.q0] -> [y XOR f(q2.q1.q0)].[q2.q1.q0] | U23: 0 | V23: 0 | W23: 0 | X23: 0 | Y23: 0 | Z23: 0 | AA23: 0 | AB23: 0 | AC23: 0.25 | AD23: 0.25 | AE23: -0.75 | AF23: 0.25 | AG23: 0.25 | AH23: 0.25 | AI23: 0.25 | AJ23: 0.25
B24: Atenção: A matriz abaixo NÃO é simétrica. [ bra2 = bra1.(BD)t ] | H24: <- Lembrar que para usar bras, o bra deve multiplicar a transposta da matriz abaixo | U24: 0 | V24: 0 | W24: 0 | X24: 0 | Y24: 0 | Z24: 0 | AA24: 0 | AB24: 0 | AC24: 0.25 | AD24: 0.25 | AE24: 0.25 | AF24: -0.75 | AG24: 0.25 | AH24: 0.25 | AI24: 0.25 | AJ24: 0.25
E25: [ ket2 = (BD).ket1 ] | U25: 0 | V25: 0 | W25: 0 | X25: 0 | Y25: 0 | Z25: 0 | AA25: 0 | AB25: 0 | AC25: 0.25 | AD25: 0.25 | AE25: 0.25 | AF25: 0.25 | AG25: -0.75 | AH25: 0.25 | AI25: 0.25 | AJ25: 0.25
U26: 0 | V26: 0 | W26: 0 | X26: 0 | Y26: 0 | Z26: 0 | AA26: 0 | AB26: 0 | AC26: 0.25 | AD26: 0.25 | AE26: 0.25 | AF26: 0.25 | AG26: 0.25 | AH26: -0.75 | AI26: 0.25 | AJ26: 0.25
B27: 0.000 | C27: 0.001 | D27: 0.010 | E27: 0.011 | F27: 0.100 | G27: 0.101 | H27: 0.110 | I27: 0.111 | J27: 1.000 | K27: 1.001 | L27: 1.010 | M27: 1.011 | N27: 1.100 | O27: 1.101 | P27: 1.110 | Q27: 1.111 | U27: 0 | V27: 0 | W27: 0 | X27: 0 | Y27: 0 | Z27: 0 | AA27: 0 | AB27: 0 | AC27: 0.25 | AD27: 0.25 | AE27: 0.25 | AF27: 0.25 | AG27: 0.25 | AH27: 0.25 | AI27: -0.75 | AJ27: 0.25
A28: {=TRANSPOSE(B27:Q27)} -> 0.000 | B28: 1 | C28: 0 | D28: 0 | E28: 0 | F28: 0 | G28: 0 | H28: 0 | I28: 0 | J28: 0 | K28: 0 | L28: 0 | M28: 0 | N28: 0 | O28: 0 | P28: 0 | Q28: 0 | U28: 0 | V28: 0 | W28: 0 | X28: 0 | Y28: 0 | Z28: 0 | AA28: 0 | AB28: 0 | AC28: 0.25 | AD28: 0.25 | AE28: 0.25 | AF28: 0.25 | AG28: 0.25 | AH28: 0.25 | AI28: 0.25 | AJ28: -0.75
A29: 0.001 | B29: 0 | C29: 1 | D29: 0 | E29: 0 | F29: 0 | G29: 0 | H29: 0 | I29: 0 | J29: 0 | K29: 0 | L29: 0 | M29: 0 | N29: 0 | O29: 0 | P29: 0 | Q29: 0
A30: 0.010 | B30: 0 | C30: 0 | D30: 1 | E30: 0 | F30: 0 | G30: 0 | H30: 0 | I30: 0 | J30: 0 | K30: 0 | L30: 0 | M30: 0 | N30: 0 | O30: 0 | P30: 0 | Q30: 0
A31: 0.011 | B31: 0 | C31: 0 | D31: 0 | E31: 1 | F31: 0 | G31: 0 | H31: 0 | I31: 0 | J31: 0 | K31: 0 | L31: 0 | M31: 0 | N31: 0 | O31: 0 | P31: 0 | Q31: 0 | U31: Banco de Dados em Formato de Tabela - Preparado para uma consulta via Bits
A32: 0.100 | B32: 0 | C32: 0 | D32: 0 | E32: 0 | F32: 0 | G32: 0 | H32: 0 | I32: 0 | J32: 0 | K32: 0 | L32: 0 | M32: 0 | N32: 1 | O32: 0 | P32: 0 | Q32: 0 | U32: Endereço | V32: Resultado | W32: Valor
A33: 0.101 | B33: 0 | C33: 0 | D33: 0 | E33: 0 | F33: 0 | G33: 1 | H33: 0 | I33: 0 | J33: 0 | K33: 0 | L33: 0 | M33: 0 | N33: 0 | O33: 0 | P33: 0 | Q33: 0 | U33: 0.0.0 | V33: 0 | W33: Alice
A34: 0.110 | B34: 0 | C34: 0 | D34: 0 | E34: 0 | F34: 0 | G34: 0 | H34: 1 | I34: 0 | J34: 0 | K34: 0 | L34: 0 | M34: 0 | N34: 0 | O34: 0 | P34: 0 | Q34: 0 | U34: 0.0.1 | V34: 0 | W34: Bernardo
A35: 0.111 | B35: 0 | C35: 0 | D35: 0 | E35: 0 | F35: 0 | G35: 0 | H35: 0 | I35: 1 | J35: 0 | K35: 0 | L35: 0 | M35: 0 | N35: 0 | O35: 0 | P35: 0 | Q35: 0 | U35: 0.1.0 | V35: 0 | W35: Cristina
A36: 1.000 | B36: 0 | C36: 0 | D36: 0 | E36: 0 | F36: 0 | G36: 0 | H36: 0 | I36: 0 | J36: 1 | K36: 0 | L36: 0 | M36: 0 | N36: 0 | O36: 0 | P36: 0 | Q36: 0 | U36: 0.1.1 | V36: 0 | W36: Eduardo
A37: 1.001 | B37: 0 | C37: 0 | D37: 0 | E37: 0 | F37: 0 | G37: 0 | H37: 0 | I37: 0 | J37: 0 | K37: 1 | L37: 0 | M37: 0 | N37: 0 | O37: 0 | P37: 0 | Q37: 0 | U37: 1.0.0 | V37: 1 | W37: Fernanda
A38: 1.010 | B38: 0 | C38: 0 | D38: 0 | E38: 0 | F38: 0 | G38: 0 | H38: 0 | I38: 0 | J38: 0 | K38: 0 | L38: 1 | M38: 0 | N38: 0 | O38: 0 | P38: 0 | Q38: 0 | U38: 1.0.1 | V38: 0 | W38: Gustavo
A39: 1.011 | B39: 0 | C39: 0 | D39: 0 | E39: 0 | F39: 0 | G39: 0 | H39: 0 | I39: 0 | J39: 0 | K39: 0 | L39: 0 | M39: 1 | N39: 0 | O39: 0 | P39: 0 | Q39: 0 | U39: 1.1.0 | V39: 0 | W39: Hélia
A40: 1.100 | B40: 0 | C40: 0 | D40: 0 | E40: 0 | F40: 1 | G40: 0 | H40: 0 | I40: 0 | J40: 0 | K40: 0 | L40: 0 | M40: 0 | N40: 0 | O40: 0 | P40: 0 | Q40: 0 | U40: 1.1.1 | V40: 0 | W40: Ignácio
A41: 1.101 | B41: 0 | C41: 0 | D41: 0 | E41: 0 | F41: 0 | G41: 0 | H41: 0 | I41: 0 | J41: 0 | K41: 0 | L41: 0 | M41: 0 | N41: 0 | O41: 1 | P41: 0 | Q41: 0
A42: 1.110 | B42: 0 | C42: 0 | D42: 0 | E42: 0 | F42: 0 | G42: 0 | H42: 0 | I42: 0 | J42: 0 | K42: 0 | L42: 0 | M42: 0 | N42: 0 | O42: 0 | P42: 1 | Q42: 0
...
